<?xml version="1.0" ?>
<sdf version="1.7">
  <model name="simple_car">
    <pose>0 0 0 0 0 0</pose>

    <!-- Chassis -->
    <link name="chassis">
      <pose>0 0 0.25 0 0 0</pose>
      <collision name="chassis_collision">
        <geometry>
          <box>
            <size>1.0 0.5 0.25</size>
          </box>
        </geometry>
      </collision>
      <visual name="chassis_visual">
        <geometry>
          <box>
            <size>1.0 0.5 0.25</size>
          </box>
        </geometry>
        <material>
          <ambient>0.8 0.1 0.1 1</ambient>
          <diffuse>0.8 0.1 0.1 1</diffuse>
        </material>
      </visual>
      <inertial>
        <mass>2.0</mass>
        <inertia>
          <ixx>0.1</ixx>
          <iyy>0.2</iyy>
          <izz>0.3</izz>
          <ixy>0.0</ixy>
          <ixz>0.0</ixz>
          <iyz>0.0</iyz>
        </inertia>
      </inertial>
    </link>

    <!-- Wheels -->
    <link name="wheel_fl">
      <pose>0.4 0.25 0.05 3 0 0</pose>
      <collision name="wheel_fl_collision">
        <geometry>
          <cylinder>
            <radius>0.1</radius>
            <length>0.05</length>
          </cylinder>
        </geometry>
      </collision>
      <visual name="wheel_fl_visual">
        <geometry>
          <cylinder>
            <radius>0.1</radius>
            <length>0.05</length>
          </cylinder>
        </geometry>
        <material>
          <ambient>0.1 0.1 0.1 1</ambient>
          <diffuse>0.1 0.1 0.1 1</diffuse>
        </material>
      </visual>
      <inertial>
        <mass>0.3</mass>
        <inertia>
          <ixx>0.001</ixx>
          <iyy>0.001</iyy>
          <izz>0.001</izz>
          <ixy>0.0</ixy>
          <ixz>0.0</ixz>
          <iyz>0.0</iyz>
        </inertia>
      </inertial>
    </link>

    <link name="wheel_fr">
      <pose>0.4 -0.25 0.05 0 0 0</pose>
      <collision name="wheel_fr_collision">
        <geometry>
          <cylinder>
            <radius>0.1</radius>
            <length>0.05</length>
          </cylinder>
        </geometry>
      </collision>
      <visual name="wheel_fr_visual">
        <geometry>
          <cylinder>
            <radius>0.1</radius>
            <length>0.05</length>
          </cylinder>
        </geometry>
        <material>
          <ambient>0.1 0.1 0.1 1</ambient>
          <diffuse>0.1 0.1 0.1 1</diffuse>
        </material>
      </visual>
      <inertial>
        <mass>0.3</mass>
        <inertia>
          <ixx>0.001</ixx>
          <iyy>0.001</iyy>
          <izz>0.001</izz>
          <ixy>0.0</ixy>
          <ixz>0.0</ixz>
          <iyz>0.0</iyz>
        </inertia>
      </inertial>
    </link>

    <link name="wheel_rl">
      <pose>-0.4 0.25 0.05 0 0 0</pose>
      <collision name="wheel_rl_collision">
        <geometry>
          <cylinder>
            <radius>0.1</radius>
            <length>0.05</length>
          </cylinder>
        </geometry>
      </collision>
      <visual name="wheel_rl_visual">
        <geometry>
          <cylinder>
            <radius>0.1</radius>
            <length>0.05</length>
          </cylinder>
        </geometry>
        <material>
          <ambient>0.1 0.1 0.1 1</ambient>
          <diffuse>0.1 0.1 0.1 1</diffuse>
        </material>
      </visual>
      <inertial>
        <mass>0.3</mass>
        <inertia>
          <ixx>0.001</ixx>
          <iyy>0.001</iyy>
          <izz>0.001</izz>
          <ixy>0.0</ixy>
          <ixz>0.0</ixz>
          <iyz>0.0</iyz>
        </inertia>
      </inertial>
    </link>

    <link name="wheel_rr">
      <pose>-0.4 -0.25 0.05 0 0 0</pose>
      <collision name="wheel_rr_collision">
        <geometry>
          <cylinder>
            <radius>0.1</radius>
            <length>0.05</length>
          </cylinder>
        </geometry>
      </collision>
      <visual name="wheel_rr_visual">
        <geometry>
          <cylinder>
            <radius>0.1</radius>
            <length>0.05</length>
          </cylinder>
        </geometry>
        <material>
          <ambient>0.1 0.1 0.1 1</ambient>
          <diffuse>0.1 0.1 0.1 1</diffuse>
        </material>
      </visual>
      <inertial>
        <mass>0.3</mass>
        <inertia>
          <ixx>0.001</ixx>
          <iyy>0.001</iyy>
          <izz>0.001</izz>
          <ixy>0.0</ixy>
          <ixz>0.0</ixz>
          <iyz>0.0</iyz>
        </inertia>
      </inertial>
    </link>

    <!-- Joints -->
    <joint name="joint_fl" type="revolute">
      <parent>chassis</parent>
      <child>wheel_fl</child>
      <pose>0.4 0.25 0.05 0 0 0</pose>
      <axis>
        <xyz>0 1 0</xyz>
        <limit>
          <lower>-1.5708</lower>
          <upper>1.5708</upper>
        </limit>
      </axis>
    </joint>

    <joint name="joint_fr" type="revolute">
      <parent>chassis</parent>
      <child>wheel_fr</child>
      <pose>0.4 -0.25 0.05 0 0 0</pose>
      <axis>
        <xyz>0 1 0</xyz>
        <limit>
          <lower>-1.5708</lower>
          <upper>1.5708</upper>
        </limit>
      </axis>
    </joint>

    <joint name="joint_rl" type="revolute">
      <parent>chassis</parent>
      <child>wheel_rl</child>
      <pose>-0.4 0.25 0.05 0 0 0</pose>
      <axis>
        <xyz>0 1 0</xyz>
        <limit>
          <lower>-1.5708</lower>
          <upper>1.5708</upper>
        </limit>
      </axis>
    </joint>

    <joint name="joint_rr" type="revolute">
      <parent>chassis</parent>
      <child>wheel_rr</child>
      <pose>-0.4 -0.25 0.05 0 0 0</pose>
      <axis>
        <xyz>0 1 0</xyz>
        <limit>
          <lower>-1.5708</lower>
          <upper>1.5708</upper>
        </limit>
      </axis>
    </joint>
  </model>
</sdf>
